Workbook

Sheet max manual challan table
B1: CCTV Challan | D1: Device Challan | F1: Manual Challan | H1: Sub Total
A2: RTO Office | B2: Sum of Total Challans | C2: Sum of Challans Pending | D2: Sum of Total Challans | E2: Sum of Challans Pending | F2: Sum of Total Challans | G2: Sum of Challans Pending | H2: Sum of Total Challans | I2: Sum of Challans Pending | J2: manual challan | K2: % in pendency | L2: Challan by device
A3: Yawatmal | B3: 0 | C3: 0 | D3: 143 | E3: 21 | F3: 0 | G3: 0 | H3: =B3+D3+F3 -> 143 | I3: =C3+E3+G3 -> 21 | J3: =(F3/H3) -> 0 | K3: =I3/H3 -> 0.14685315 | L3: =D3/H3 -> 1
A4: Kalyan | B4: 0 | C4: 0 | D4: 127 | E4: 25 | F4: 0 | G4: 0 | H4: =B4+D4+F4 -> 127 | I4: =C4+E4+G4 -> 25 | J4: =(F4/H4) -> 0 | K4: =I4/H4 -> 0.19685039 | L4: =D4/H4 -> 1
A5: Nagpur (east) | B5: 0 | C5: 0 | D5: 85 | E5: 24 | F5: 0 | G5: 0 | H5: =B5+D5+F5 -> 85 | I5: =C5+E5+G5 -> 24 | J5: =(F5/H5) -> 0 | K5: =I5/H5 -> 0.28235294 | L5: =D5/H5 -> 1
A6: Gadchiroli | B6: 0 | C6: 0 | D6: 168 | E6: 59 | F6: 0 | G6: 0 | H6: =B6+D6+F6 -> 168 | I6: =C6+E6+G6 -> 59 | J6: =(F6/H6) -> 0 | K6: =I6/H6 -> 0.35119048 | L6: =D6/H6 -> 1
A7: Ambejogai | B7: 0 | C7: 0 | D7: 24 | E7: 10 | F7: 0 | G7: 0 | H7: =B7+D7+F7 -> 24 | I7: =C7+E7+G7 -> 10 | J7: =(F7/H7) -> 0 | K7: =I7/H7 -> 0.41666667 | L7: =D7/H7 -> 1
A8: Pen (Raigad) | B8: 0 | C8: 0 | D8: 186 | E8: 91 | F8: 0 | G8: 0 | H8: =B8+D8+F8 -> 186 | I8: =C8+E8+G8 -> 91 | J8: =(F8/H8) -> 0 | K8: =I8/H8 -> 0.48924731 | L8: =D8/H8 -> 1
A9: Malegaon | B9: 0 | C9: 0 | D9: 171 | E9: 94 | F9: 0 | G9: 0 | H9: =B9+D9+F9 -> 171 | I9: =C9+E9+G9 -> 94 | J9: =(F9/H9) -> 0 | K9: =I9/H9 -> 0.5497076 | L9: =D9/H9 -> 1
A10: Borivali | B10: 0 | C10: 0 | D10: 73 | E10: 46 | F10: 0 | G10: 0 | H10: =B10+D10+F10 -> 73 | I10: =C10+E10+G10 -> 46 | J10: =(F10/H10) -> 0 | K10: =I10/H10 -> 0.63013699 | L10: =D10/H10 -> 1
A11: Baramati | B11: 0 | C11: 0 | D11: 167 | E11: 110 | F11: 0 | G11: 0 | H11: =B11+D11+F11 -> 167 | I11: =C11+E11+G11 -> 110 | J11: =(F11/H11) -> 0 | K11: =I11/H11 -> 0.65868263 | L11: =D11/H11 -> 1
A12: Ratnagiri | B12: 0 | C12: 0 | D12: 258 | E12: 181 | F12: 0 | G12: 0 | H12: =B12+D12+F12 -> 258 | I12: =C12+E12+G12 -> 181 | J12: =(F12/H12) -> 0 | K12: =I12/H12 -> 0.70155039 | L12: =D12/H12 -> 1
A13: Akola | B13: 0 | C13: 0 | D13: 400 | E13: 305 | F13: 0 | G13: 0 | H13: =B13+D13+F13 -> 400 | I13: =C13+E13+G13 -> 305 | J13: =(F13/H13) -> 0 | K13: =I13/H13 -> 0.7625 | L13: =D13/H13 -> 1
A14: Pimpri-chinchwad | B14: 0 | C14: 0 | D14: 745 | E14: 575 | F14: 0 | G14: 0 | H14: =B14+D14+F14 -> 745 | I14: =C14+E14+G14 -> 575 | J14: =(F14/H14) -> 0 | K14: =I14/H14 -> 0.77181208 | L14: =D14/H14 -> 1
... A50: Beed | B50: 42 | C50: 40 | D50: 22 | E50: 2 | F50: 1 | G50: 1 | H50: =B50+D50+F50 -> 65 | I50: =C50+E50+G50 -> 43 | J50: =(F50/H50) -> 0.015384615 | K50: =I50/H50 -> 0.66153846 | L50: =D50/H50 -> 0.33846154
A51: Sindhudurg (kudal) | B51: 0 | C51: 0 | D51: 0 | E51: 0 | F51: 0 | G51: 0 | H51: =B51+D51+F51 -> 0 | I51: =C51+E51+G51 -> 0 | J51: 0 | K51: 0 | L51: 0
A52: Srirampur | B52: 0 | C52: 0 | D52: 0 | E52: 0 | F52: 0 | G52: 0 | H52: =B52+D52+F52 -> 0 | I52: =C52+E52+G52 -> 0 | J52: 0 | K52: 0 | L52: 0

Sheet Final Ranking-Nov
A1: Sr No | B1: Category | C1: Code | D1: RTO | E1: Sarathi Pendency | F1: Vahan Pendency | G1: Online Revenue | H1: Challan Collection Pendency | I1: Challan collection by device | J1: Marks (100) | K1: New Rank | L1: Old rank | M1: Difference
A2: 5 | B2: A | C2: MH47 | D2: MH-47 Borivali | E2: 28.224382 | F2: 73.897801 | G2: 99.431915 | H2: 6.1531386 | I2: 100 | J2: =AVERAGE(E2:I2) -> 61.541447 | K2: 1 | L2: 8 | M2: =(L2-K2) -> 7
A3: 4 | B3: A | C3: MH12 | D3: MH-12 Pune | E3: 38.857725 | F3: 64.939939 | G3: 94.703867 | H3: 5.1843755 | I3: 98.81 | J3: =AVERAGE(E3:I3) -> 60.499181 | K3: 2 | L3: 2 | M3: =(L3-K3) -> 0
A4: 10 | B4: A | C4: MH03 | D4: MH-03 Mumbai (East) | E4: 34.794584 | F4: 66.295658 | G4: 95.483621 | H4: 4.0989333 | I4: 98.3 | J4: =AVERAGE(E4:I4) -> 59.794559 | K4: 3 | L4: =VLOOKUP(C4,'Final Ranking Oct'!C4:K53,9,0) -> 11 | M4: =(L4-K4) -> 8
A5: 9 | B5: A | C5: MH34 | D5: MH-34 Chandrapur | E5: 23.919471 | F5: 61.059973 | G5: 96.66694 | H5: 13.590509 | I5: 98.94 | J5: =AVERAGE(E5:I5) -> 58.835378 | K5: 4 | L5: 4 | M5: =(L5-K5) -> 0
A6: 2 | B6: A | C6: MH15 | D6: MH-15 Nashik | E6: 52.794283 | F6: 30.532621 | G6: 98.1246 | H6: 10.001505 | I6: 99.71 | J6: =AVERAGE(E6:I6) -> 58.232602 | K6: 5 | L6: 1 | M6: =(L6-K6) -> -4
A7: 12 | B7: A | C7: MH01 | D7: MH-01 Mumbai (Central) | E7: 35.252538 | F7: 48.585252 | G7: 98.753116 | H7: 5.3997851 | I7: 99 | J7: =AVERAGE(E7:I7) -> 57.398138 | K7: 6 | L7: =VLOOKUP(C7,'Final Ranking Oct'!C2:K51,9,0) -> 12 | M7: =(L7-K7) -> 6
A8: 3 | B8: A | C8: MH14 | D8: MH-14 Pimpri-Chinchwad | E8: 36.50145 | F8: 43.495409 | G8: 99.198278 | H8: 4.2176634 | I8: 100 | J8: =AVERAGE(E8:I8) -> 56.68256 | K8: 7 | L8: 3 | M8: =(L8-K8) -> -4
A9: 1 | B9: A | C9: MH04 | D9: MH-04 Thane | E9: 27.445458 | F9: 57.815698 | G9: 93.963658 | H9: 4.3192789 | I9: 98.19 | J9: =AVERAGE(E9:I9) -> 56.346819 | K9: 8 | L9: =VLOOKUP(C9,'Final Ranking Oct'!C5:K54,9,0) -> 6 | M9: =(L9-K9) -> -2
A10: 14 | B10: A | C10: MH09 | D10: MH-09 Kolhapur | E10: 24.469834 | F10: 48.641251 | G10: 95.258082 | H10: 11.273236 | I10: 97 | J10: =AVERAGE(E10:I10) -> 55.32848 | K10: 9 | L10: 5 | M10: =(L10-K10) -> -4
A11: 11 | B11: A | C11: MH05 | D11: MH-05 Kalyan | E11: 24.824023 | F11: 50.851671 | G11: 96.510878 | H11: 5.3200099 | I11: 97.23 | J11: =AVERAGE(E11:I11) -> 54.947316 | K11: 10 | L11: =VLOOKUP(C11,'Final Ranking Oct'!C6:K55,9,0) -> 10 | M11: =(L11-K11) -> 0
A12: 13 | B12: A | C12: MH48 | D12: MH-48 Vasai | E12: 17.784191 | F12: 51.953552 | G12: 96.496249 | H12: 5.3238111 | I12: 97.5 | J12: =AVERAGE(E12:I12) -> 53.811561 | K12: 11 | L12: 14 | M12: =(L12-K12) -> 3
A13: 7 | B13: A | C13: MH43 | D13: MH-43 Vashi | E13: 32.61129 | F13: 51.433135 | G13: 98.446694 | H13: 4.2264169 | I13: 76.7 | J13: =AVERAGE(E13:I13) -> 52.683507 | K13: 12 | L13: =VLOOKUP(C13,'Final Ranking Oct'!C13:K62,9,0) -> 13 | M13: =(L13-K13) -> 1
A14: 6 | B14: A | C14: MH46 | D14: MH-46 Panvel | E14: 20.718237 | F14: 68.003944 | G14: 99.458724 | H14: 4.879577 | I14: 66.35 | J14: =AVERAGE(E14:I14) -> 51.882096 | K14: 13 | L14: 7 | M14: =(L14-K14) -> -6
A15: 8 | B15: A | C15: MH20 | D15: MH-20 Aurangabad | E15: 28.9402 | F15: 28.204533 | G15: 97.272017 | H15: 4.9360917 | I15: 99.28 | J15: =AVERAGE(E15:I15) -> 51.726568 | K15: 14 | L15: 9 | M15: =(L15-K15) -> -5
A16: 15 | B16: A | C16: MH02 | D16: MH-02 Mumbai (West) | E16: 37.244595 | F16: 35.809796 | G16: 98.734005 | H16: 3.3752561 | I16: 54.07 | J16: =AVERAGE(E16:I16) -> 45.84673 | K16: 15 | L16: =VLOOKUP(C16,'Final Ranking Oct'!C3:K52,9,0) -> 15 | M16: =(L16-K16) -> 0
A17: 16 | B17: B | C17: MH40 | D17: MH-40 Nagpur (Rural) | E17: 20.547046 | F17: 80.222843 | G17: 96.189873 | H17: 100 | I17: 99.97 | J17: =AVERAGE(E17:I17) -> 79.385953 | K17: 1 | L17: 6 | M17: =(L17-K17) -> 5
A18: 18 | B18: B | C18: MH11 | D18: MH-11 Satara | E18: 100 | F18: 100 | G18: 99.496254 | H18: 3.9115148 | I18: 91.03 | J18: =AVERAGE(E18:I18) -> 78.887554 | K18: 2 | L18: 1 | M18: =(L18-K18) -> -1
A19: 17 | B19: B | C19: MH24 | D19: MH-24 Latur | E19: 49.931933 | F19: 88.396586 | G19: 96.487595 | H19: 34.42297 | I19: 97.56 | J19: =AVERAGE(E19:I19) -> 73.359817 | K19: 3 | L19: 8 | M19: =(L19-K19) -> 5
A20: 20 | B20: B | C20: MH13 | D20: MH-13 Solapur | E20: 58.224426 | F20: 41.001485 | G20: 96.858393 | H20: 18.888777 | I20: 97.09 | J20: =AVERAGE(E20:I20) -> 62.412616 | K20: 4 | L20: 3 | M20: =(L20-K20) -> -1
A21: 19 | B21: B | C21: MH27 | D21: MH-27 Amravati | E21: 43.479284 | F21: 70.991559 | G21: 96.527435 | H21: 6.9425809 | I21: 91.7 | J21: =AVERAGE(E21:I21) -> 61.928172 | K21: 5 | L21: 4 | M21: =(L21-K21) -> -1
A22: 23 | B22: B | C22: MH18 | D22: MH-18 Dhule | E22: 36.33453 | F22: 69.557384 | G22: 98.602997 | H22: 5.0694995 | I22: 97.93 | J22: =AVERAGE(E22:I22) -> 61.498882 | K22: 6 | L22: 5 | M22: =(L22-K22) -> -1
A23: 26 | B23: B | C23: MH06 | D23: MH-06 Pen (Raigad) | E23: 35.129494 | F23: 53.522487 | G23: 98.979288 | H23: 7.1207693 | I23: 100 | J23: =AVERAGE(E23:I23) -> 58.950408 | K23: 7 | L23: =VLOOKUP(C23,'Final Ranking Oct'!C17:K66,9,0) -> 12 | M23: =(L23-K23) -> 5
A24: 27 | B24: B | C24: MH26 | D24: MH-26 Nanded | E24: 31.958875 | F24: 61.017659 | G24: 95.548071 | H24: 6.190273 | I24: 95.42 | J24: =AVERAGE(E24:I24) -> 58.026976 | K24: 8 | L24: =VLOOKUP(C24,'Final Ranking Oct'!C26:K75,9,0) -> 10 | M24: =(L24-K24) -> 2
A25: 30 | B25: B | C25: MH49 | D25: MH-49 Nagpur (East) | E25: 19.550396 | F25: 65.491475 | G25: 96.060825 | H25: 6.2523828 | I25: 100 | J25: =AVERAGE(E25:I25) -> 57.471016 | K25: 9 | L25: 11 | M25: =(L25-K25) -> 2
A26: 21 | B26: B | C26: MH42 | D26: MH-42 Baramati | E26: 29.774278 | F26: 50.635995 | G26: 96.071354 | H26: 6.536582 | I26: 100 | J26: =AVERAGE(E26:I26) -> 56.603642 | K26: 10 | L26: 9 | M26: =(L26-K26) -> -1
A27: 28 | B27: B | C27: MH10 | D27: MH-10 Sangli | E27: 38.914485 | F27: 44.929318 | G27: 97.995029 | H27: 5.6407366 | I27: 93.29 | J27: =AVERAGE(E27:I27) -> 56.153914 | K27: 11 | L27: =VLOOKUP(C27,'Final Ranking Oct'!C18:K67,9,0) -> 13 | M27: =(L27-K27) -> 2
A28: 24 | B28: B | C28: MH31 | D28: MH-31 Nagpur_City | E28: 23.287035 | F28: 63.360876 | G28: 96.530501 | H28: 7.0148685 | I28: 88.36 | J28: =AVERAGE(E28:I28) -> 55.710656 | K28: 12 | L28: =VLOOKUP(C28,'Final Ranking Oct'!C28:K77,9,0) -> 14 | M28: =(L28-K28) -> 2
A29: 25 | B29: B | C29: MH16 | D29: MH-16 Ahmednagar | E29: 28.553822 | F29: 77.640443 | G29: 94.323322 | H29: 4.214106 | I29: 69.35 | J29: =AVERAGE(E29:I29) -> 54.816339 | K29: 13 | L29: =VLOOKUP(C29,'Final Ranking Oct'!C21:K70,9,0) -> 7 | M29: =(L29-K29) -> -6
A30: 29 | B30: B | C30: MH19 | D30: MH-19 Jalgaon | E30: 24.269326 | F30: 33.02003 | G30: 98.334397 | H30: 6.2962591 | I30: 96.56 | J30: =AVERAGE(E30:I30) -> 51.696003 | K30: 14 | L30: =VLOOKUP(C30,'Final Ranking Oct'!C24:K73,9,0) -> 15 | M30: =(L30-K30) -> 1
A31: 22 | B31: B | C31: MH17 | D31: MH-17 Shrirampur | E31: 38.744644 | F31: 55.068729 | G31: 100 | H31: 3.3905956 | I31: 0 | J31: =AVERAGE(E31:I31) -> 39.440794 | K31: 15 | L31: 2 | M31: =(L31-K31) -> -13
A32: 41 | B32: C | C32: MH29 | D32: MH-29 Yawatmal | E32: 29.74036 | F32: 87.301904 | G32: 93.859272 | H32: 4.3899709 | I32: 100 | J32: =AVERAGE(E32:I32) -> 63.058301 | K32: 1 | L32: =VLOOKUP(C32,'Final Ranking Oct'!C39:K88,9,0) -> 13 | M32: =(L32-K32) -> 12
A33: 31 | B33: C | C33: MH32 | D33: MH-32 Wardha | E33: 60.582937 | F33: 57.044049 | G33: 94.171854 | H33: 5.5266598 | I33: 90.42 | J33: =AVERAGE(E33:I33) -> 61.5491 | K33: 2 | L33: 2 | M33: =(L33-K33) -> 0
A34: 42 | B34: C | C34: MH25 | D34: MH-25 Osmanabad | E34: 42.460911 | F34: 67.422224 | G34: 94.627421 | H34: 3.5727902 | I34: 95.45 | J34: =AVERAGE(E34:I34) -> 60.706669 | K34: 3 | L34: =VLOOKUP(C34,'Final Ranking Oct'!C37:K86,9,0) -> 10 | M34: =(L34-K34) -> 7
A35: 33 | B35: C | C35: MH33 | D35: MH-33 Gadchiroli | E35: 42.460911 | F35: 30.268882 | G35: 93.908737 | H35: 36.071439 | I35: 100 | J35: =AVERAGE(E35:I35) -> 60.541994 | K35: 4 | L35: 4 | M35: =(L35-K35) -> 0
A36: 34 | B36: C | C36: MH36 | D36: MH-36 Bhandara | E36: 36.216874 | F36: 76.126634 | G36: 93.277811 | H36: 5.9498481 | I36: 91 | J36: =AVERAGE(E36:I36) -> 60.514233 | K36: 5 | L36: 8 | M36: =(L36-K36) -> 3
A37: 44 | B37: C | C37: MH35 | D37: MH-35 Gondia | E37: 43.764897 | F37: 62.482699 | G37: 94.029429 | H37: 6.193398 | I37: 91.76 | J37: =AVERAGE(E37:I37) -> 59.646085 | K37: 6 | L37: 5 | M37: =(L37-K37) -> -1
A38: 46 | B38: C | C38: MH08 | D38: MH-08 Ratnagiri | E38: 20.04711 | F38: 75.928513 | G38: 95.494701 | H38: 5.615566 | I38: 100 | J38: =AVERAGE(E38:I38) -> 59.417178 | K38: 7 | L38: =VLOOKUP(C38,'Final Ranking Oct'!C33:K82,9,0) -> 18 | M38: =(L38-K38) -> 11
A39: 49 | B39: C | C39: MH39 | D39: MH-39 Nandurbar | E39: 39.1969 | F39: 61.531334 | G39: 89.586039 | H39: 4.3907182 | I39: 95.59 | J39: =AVERAGE(E39:I39) -> 58.058998 | K39: 8 | L39: 15 | M39: =(L39-K39) -> 7
A40: 36 | B40: C | C40: MH30 | D40: MH-30 Akola | E40: 50.659072 | F40: 37.79568 | G40: 94.023464 | H40: 4.2377261 | I40: 100 | J40: =AVERAGE(E40:I40) -> 57.343188 | K40: 9 | L40: 7 | M40: =(L40-K40) -> -2
...

Sheet Final Ranking Oct
A1: Sr No | B1: Category | C1: Code | D1: RTO | E1: Sarathi Pendency | F1: Vahan Pendency | G1: Online Revenue | H1: Challan Collection Pendency | I1: Challan collection by device | J1: Marks (100) | K1: New Rank | L1: Old rank
A2: 2 | B2: A | C2: MH15 | D2: MH-15 Nashik | E2: =VLOOKUP(C2,'[1]sarathi pendency OCT 2021'!$B$2:$G$51,6,0) -> 57.761857 | F2: =VLOOKUP(C2,'[1]vahan pendency_oct2021'!$C$2:$H$51,6,0) -> 49.265514 | G2: =VLOOKUP(C2,'[1]Online Revenue_OCT2021'!$B$2:$O$51,14,0) -> 96.771568 | H2: =VLOOKUP('[1]Final Ranking Nov-21'!C3,'[1]challan pendency'!$B$3:$L$53,11,0) -> 2.8866857 | I2: =VLOOKUP(C2,'[1]challan online'!$G$3:$Q$51,11,0) -> 100 | J2: =AVERAGE(E2:I2) -> 61.337125 | K2: 1 | L2: 1
A3: 4 | B3: A | C3: MH12 | D3: MH-12 Pune | E3: =VLOOKUP(C3,'[1]sarathi pendency OCT 2021'!$B$2:$G$51,6,0) -> 41.551297 | F3: =VLOOKUP(C3,'[1]vahan pendency_oct2021'!$C$2:$H$51,6,0) -> 50.773524 | G3: =VLOOKUP(C3,'[1]Online Revenue_OCT2021'!$B$2:$O$51,14,0) -> 98.495056 | H3: =VLOOKUP('[1]Final Ranking Nov-21'!C4,'[1]challan pendency'!$B$3:$L$53,11,0) -> 2.4438136 | I3: =VLOOKUP(C3,'[1]challan online'!$G$3:$Q$51,11,0) -> 98.438855 | J3: =AVERAGE(E3:I3) -> 58.340509 | K3: 2 | L3: 2
A4: 3 | B4: A | C4: MH14 | D4: MH-14 Pimpri-Chinchwad | E4: =VLOOKUP(C4,'[1]sarathi pendency OCT 2021'!$B$2:$G$51,6,0) -> 17.040144 | F4: =VLOOKUP(C4,'[1]vahan pendency_oct2021'!$C$2:$H$51,6,0) -> 71.591808 | G4: =VLOOKUP(C4,'[1]Online Revenue_OCT2021'!$B$2:$O$51,14,0) -> 99.184779 | H4: =VLOOKUP('[1]Final Ranking Nov-21'!C6,'[1]challan pendency'!$B$3:$L$53,11,0) -> 7.3713391 | I4: =VLOOKUP(C4,'[1]challan online'!$G$3:$Q$51,11,0) -> 86.038961 | J4: =AVERAGE(E4:I4) -> 56.245406 | K4: 3 | L4: 3
A5: 9 | B5: A | C5: MH34 | D5: MH-34 Chandrapur | E5: =VLOOKUP(C5,'[1]sarathi pendency OCT 2021'!$B$2:$G$51,6,0) -> 18.737155 | F5: =VLOOKUP(C5,'[1]vahan pendency_oct2021'!$C$2:$H$51,6,0) -> 68.694996 | G5: =VLOOKUP(C5,'[1]Online Revenue_OCT2021'!$B$2:$O$51,14,0) -> 89.550658 | H5: =VLOOKUP('[1]Final Ranking Nov-21'!C5,'[1]challan pendency'!$B$3:$L$53,11,0) -> 14.576493 | I5: =VLOOKUP(C5,'[1]challan online'!$G$3:$Q$51,11,0) -> 98.881119 | J5: =AVERAGE(E5:I5) -> 58.088084 | K5: 4 | L5: 4
A6: 14 | B6: A | C6: MH09 | D6: MH-09 Kolhapur | E6: =VLOOKUP(C6,'[1]sarathi pendency OCT 2021'!$B$2:$G$51,6,0) -> 41.64234 | F6: =VLOOKUP(C6,'[1]vahan pendency_oct2021'!$C$2:$H$51,6,0) -> 27.521559 | G6: =VLOOKUP(C6,'[1]Online Revenue_OCT2021'!$B$2:$O$51,14,0) -> 97.911117 | H6: =VLOOKUP('[1]Final Ranking Nov-21'!C7,'[1]challan pendency'!$B$3:$L$53,11,0) -> 3.1458514 | I6: =VLOOKUP(C6,'[1]challan online'!$G$3:$Q$51,11,0) -> 99.083588 | J6: =AVERAGE(E6:I6) -> 53.860891 | K6: 5 | L6: 5
A7: 1 | B7: A | C7: MH04 | D7: MH-04 Thane | E7: =VLOOKUP(C7,'[1]sarathi pendency OCT 2021'!$B$2:$G$51,6,0) -> 26.814147 | F7: =VLOOKUP(C7,'[1]vahan pendency_oct2021'!$C$2:$H$51,6,0) -> 43.94506 | G7: =VLOOKUP(C7,'[1]Online Revenue_OCT2021'!$B$2:$O$51,14,0) -> 94.68184 | H7: =VLOOKUP('[1]Final Ranking Nov-21'!C8,'[1]challan pendency'!$B$3:$L$53,11,0) -> 2.4810933 | I7: =VLOOKUP(C7,'[1]challan online'!$G$3:$Q$51,11,0) -> 99.323345 | J7: =AVERAGE(E7:I7) -> 53.449097 | K7: 6 | L7: 6
A8: 6 | B8: A | C8: MH46 | D8: MH-46 Panvel | E8: =VLOOKUP(C8,'[1]sarathi pendency OCT 2021'!$B$2:$G$51,6,0) -> 15.104615 | F8: =VLOOKUP(C8,'[1]vahan pendency_oct2021'!$C$2:$H$51,6,0) -> 52.96282 | G8: =VLOOKUP(C8,'[1]Online Revenue_OCT2021'!$B$2:$O$51,14,0) -> 95.660537 | H8: =VLOOKUP('[1]Final Ranking Nov-21'!C10,'[1]challan pendency'!$B$3:$L$53,11,0) -> 3.5746686 | I8: =VLOOKUP(C8,'[1]challan online'!$G$3:$Q$51,11,0) -> 97.651934 | J8: =AVERAGE(E8:I8) -> 52.990915 | K8: 7 | L8: 7
A9: 5 | B9: A | C9: MH47 | D9: MH-47 Borivali | E9: =VLOOKUP(C9,'[1]sarathi pendency OCT 2021'!$B$2:$G$51,6,0) -> 16.792849 | F9: =VLOOKUP(C9,'[1]vahan pendency_oct2021'!$C$2:$H$51,6,0) -> 47.84384 | G9: =VLOOKUP(C9,'[1]Online Revenue_OCT2021'!$B$2:$O$51,14,0) -> 98.632448 | H9: =VLOOKUP('[1]Final Ranking Nov-21'!C9,'[1]challan pendency'!$B$3:$L$53,11,0) -> 3.1330657 | I9: =VLOOKUP(C9,'[1]challan online'!$G$3:$Q$51,11,0) -> 98.550725 | J9: =AVERAGE(E9:I9) -> 52.990585 | K9: 8 | L9: 8
A10: 8 | B10: A | C10: MH20 | D10: MH-20 Aurangabad | E10: =VLOOKUP(C10,'[1]sarathi pendency OCT 2021'!$B$2:$G$51,6,0) -> 16.667125 | F10: =VLOOKUP(C10,'[1]vahan pendency_oct2021'!$C$2:$H$51,6,0) -> 44.987939 | G10: =VLOOKUP(C10,'[1]Online Revenue_OCT2021'!$B$2:$O$51,14,0) -> 96.364515 | H10: =VLOOKUP('[1]Final Ranking Nov-21'!C11,'[1]challan pendency'!$B$3:$L$53,11,0) -> 3.1212125 | I10: =VLOOKUP(C10,'[1]challan online'!$G$3:$Q$51,11,0) -> 100 | J10: =AVERAGE(E10:I10) -> 52.228158 | K10: 9 | L10: 9
A11: 11 | B11: A | C11: MH05 | D11: MH-05 Kalyan | E11: =VLOOKUP(C11,'[1]sarathi pendency OCT 2021'!$B$2:$G$51,6,0) -> 18.300136 | F11: =VLOOKUP(C11,'[1]vahan pendency_oct2021'!$C$2:$H$51,6,0) -> 40.428131 | G11: =VLOOKUP(C11,'[1]Online Revenue_OCT2021'!$B$2:$O$51,14,0) -> 96.845471 | H11: =VLOOKUP('[1]Final Ranking Nov-21'!C12,'[1]challan pendency'!$B$3:$L$53,11,0) -> 2.5471971 | I11: =VLOOKUP(C11,'[1]challan online'!$G$3:$Q$51,11,0) -> 100 | J11: =AVERAGE(E11:I11) -> 51.624187 | K11: 10 | L11: 10
A12: 10 | B12: A | C12: MH03 | D12: MH-03 Mumbai (East) | E12: =VLOOKUP(C12,'[1]sarathi pendency OCT 2021'!$B$2:$G$51,6,0) -> 16.952421 | F12: =VLOOKUP(C12,'[1]vahan pendency_oct2021'!$C$2:$H$51,6,0) -> 36.543434 | G12: =VLOOKUP(C12,'[1]Online Revenue_OCT2021'!$B$2:$O$51,14,0) -> 99.031987 | H12: =VLOOKUP('[1]Final Ranking Nov-21'!C13,'[1]challan pendency'!$B$3:$L$53,11,0) -> 3.6747033 | I12: =VLOOKUP(C12,'[1]challan online'!$G$3:$Q$51,11,0) -> 98.473282 | J12: =AVERAGE(E12:I12) -> 50.935166 | K12: 11 | L12: 11
A13: 12 | B13: A | C13: MH01 | D13: MH-01 Mumbai (Central) | E13: =VLOOKUP(C13,'[1]sarathi pendency OCT 2021'!$B$2:$G$51,6,0) -> 15.925482 | F13: =VLOOKUP(C13,'[1]vahan pendency_oct2021'!$C$2:$H$51,6,0) -> 36.304803 | G13: =VLOOKUP(C13,'[1]Online Revenue_OCT2021'!$B$2:$O$51,14,0) -> 98.254211 | H13: =VLOOKUP('[1]Final Ranking Nov-21'!C14,'[1]challan pendency'!$B$3:$L$53,11,0) -> 2.9537253 | I13: =VLOOKUP(C13,'[1]challan online'!$G$3:$Q$51,11,0) -> 99.029126 | J13: =AVERAGE(E13:I13) -> 50.49347 | K13: 12 | L13: 12
A14: 7 | B14: A | C14: MH43 | D14: MH-43 Vashi | E14: =VLOOKUP(C14,'[1]sarathi pendency OCT 2021'!$B$2:$G$51,6,0) -> 14.898481 | F14: =VLOOKUP(C14,'[1]vahan pendency_oct2021'!$C$2:$H$51,6,0) -> 36.255032 | G14: =VLOOKUP(C14,'[1]Online Revenue_OCT2021'!$B$2:$O$51,14,0) -> 95.717857 | H14: =VLOOKUP('[1]Final Ranking Nov-21'!C15,'[1]challan pendency'!$B$3:$L$53,11,0) -> 3.1710806 | I14: =VLOOKUP(C14,'[1]challan online'!$G$3:$Q$51,11,0) -> 100 | J14: =AVERAGE(E14:I14) -> 50.00849 | K14: 13 | L14: 13
A15: 13 | B15: A | C15: MH48 | D15: MH-48 Vasai | E15: =VLOOKUP(C15,'[1]sarathi pendency OCT 2021'!$B$2:$G$51,6,0) -> 12.221677 | F15: =VLOOKUP(C15,'[1]vahan pendency_oct2021'!$C$2:$H$51,6,0) -> 37.103967 | G15: =VLOOKUP(C15,'[1]Online Revenue_OCT2021'!$B$2:$O$51,14,0) -> 97.047368 | H15: =VLOOKUP('[1]Final Ranking Nov-21'!C16,'[1]challan pendency'!$B$3:$L$53,11,0) -> 2.6543488 | I15: =VLOOKUP(C15,'[1]challan online'!$G$3:$Q$51,11,0) -> 100 | J15: =AVERAGE(E15:I15) -> 49.805472 | K15: 14 | L15: 14
A16: 15 | B16: A | C16: MH02 | D16: MH-02 Mumbai (West) | E16: =VLOOKUP(C16,'[1]sarathi pendency OCT 2021'!$B$2:$G$51,6,0) -> 17.377043 | F16: =VLOOKUP(C16,'[1]vahan pendency_oct2021'!$C$2:$H$51,6,0) -> 26.713602 | G16: =VLOOKUP(C16,'[1]Online Revenue_OCT2021'!$B$2:$O$51,14,0) -> 99.214763 | H16: =VLOOKUP('[1]Final Ranking Nov-21'!C17,'[1]challan pendency'!$B$3:$L$53,11,0) -> 2.7980622 | I16: =VLOOKUP(C16,'[1]challan online'!$G$3:$Q$51,11,0) -> 88.172043 | J16: =AVERAGE(E16:I16) -> 46.855103 | K16: 15 | L16: 15
A17: 18 | B17: B | C17: MH11 | D17: MH-11 Satara | E17: =VLOOKUP(C17,'[1]sarathi pendency OCT 2021'!$B$2:$G$51,6,0) -> 100 | F17: =VLOOKUP(C17,'[1]vahan pendency_oct2021'!$C$2:$H$51,6,0) -> 61.563425 | G17: =VLOOKUP(C17,'[1]Online Revenue_OCT2021'!$B$2:$O$51,14,0) -> 96.700917 | H17: =VLOOKUP('[1]Final Ranking Nov-21'!C19,'[1]challan pendency'!$B$3:$L$49,11,0) -> 15.277252 | I17: =VLOOKUP(C17,'[1]challan online'!$G$3:$Q$51,11,0) -> 100 | J17: =AVERAGE(E17:I17) -> 74.708319 | K17: 1 | L17: 1
A18: 22 | B18: B | C18: MH17 | D18: MH-17 Shrirampur | E18: =VLOOKUP(C18,'[1]sarathi pendency OCT 2021'!$B$2:$G$51,6,0) -> 31.295419 | F18: =VLOOKUP(C18,'[1]vahan pendency_oct2021'!$C$2:$H$51,6,0) -> 37.158225 | G18: =VLOOKUP(C18,'[1]Online Revenue_OCT2021'!$B$2:$O$51,14,0) -> 98.167614 | H18: =VLOOKUP('[1]Final Ranking Nov-21'!C23,'[1]challan pendency'!$B$3:$L$49,11,0) -> 3.240179 | I18: =VLOOKUP(C18,'[1]challan online'!$G$3:$Q$51,11,0) -> 100 | J18: =AVERAGE(E18:I18) -> 53.972287 | K18: 2 | L18: 2
A19: 20 | B19: B | C19: MH13 | D19: MH-13 Solapur | E19: =VLOOKUP(C19,'[1]sarathi pendency OCT 2021'!$B$2:$G$51,6,0) -> 58.276616 | F19: =VLOOKUP(C19,'[1]vahan pendency_oct2021'!$C$2:$H$51,6,0) -> 73.522199 | G19: =VLOOKUP(C19,'[1]Online Revenue_OCT2021'!$B$2:$O$51,14,0) -> 98.670716 | H19: =VLOOKUP('[1]Final Ranking Nov-21'!C21,'[1]challan pendency'!$B$3:$L$49,11,0) -> 13.750232 | I19: =VLOOKUP(C19,'[1]challan online'!$G$3:$Q$51,11,0) -> 98.692241 | J19: =AVERAGE(E19:I19) -> 68.582401 | K19: 3 | L19: 3
A20: 19 | B20: B | C20: MH27 | D20: MH-27 Amravati | E20: =VLOOKUP(C20,'[1]sarathi pendency OCT 2021'!$B$2:$G$51,6,0) -> 47.238693 | F20: =VLOOKUP(C20,'[1]vahan pendency_oct2021'!$C$2:$H$51,6,0) -> 82.276979 | G20: =VLOOKUP(C20,'[1]Online Revenue_OCT2021'!$B$2:$O$51,14,0) -> 97.639952 | H20: =VLOOKUP('[1]Final Ranking Nov-21'!C20,'[1]challan pendency'!$B$3:$L$49,11,0) -> 3.7037936 | I20: =VLOOKUP(C20,'[1]challan online'!$G$3:$Q$51,11,0) -> 100 | J20: =AVERAGE(E20:I20) -> 66.171883 | K20: 4 | L20: 4
A21: 23 | B21: B | C21: MH18 | D21: MH-18 Dhule | E21: =VLOOKUP(C21,'[1]sarathi pendency OCT 2021'!$B$2:$G$51,6,0) -> 37.277094 | F21: =VLOOKUP(C21,'[1]vahan pendency_oct2021'!$C$2:$H$51,6,0) -> 80.830295 | G21: =VLOOKUP(C21,'[1]Online Revenue_OCT2021'!$B$2:$O$51,14,0) -> 99.450221 | H21: =VLOOKUP('[1]Final Ranking Nov-21'!C24,'[1]challan pendency'!$B$3:$L$49,11,0) -> 23.02141 | I21: =VLOOKUP(C21,'[1]challan online'!$G$3:$Q$51,11,0) -> 94.301994 | J21: =AVERAGE(E21:I21) -> 66.976203 | K21: 5 | L21: 5
A22: 16 | B22: B | C22: MH40 | D22: MH-40 Nagpur (Rural) | E22: =VLOOKUP(C22,'[1]sarathi pendency OCT 2021'!$B$2:$G$51,6,0) -> 30.943917 | F22: =VLOOKUP(C22,'[1]vahan pendency_oct2021'!$C$2:$H$51,6,0) -> 71.602561 | G22: =VLOOKUP(C22,'[1]Online Revenue_OCT2021'!$B$2:$O$51,14,0) -> 93.385399 | H22: =VLOOKUP('[1]Final Ranking Nov-21'!C17,'[1]challan pendency'!$B$3:$L$49,11,0) -> 2.7980622 | I22: =VLOOKUP(C22,'[1]challan online'!$G$3:$Q$51,11,0) -> 100 | J22: =AVERAGE(E22:I22) -> 59.745988 | K22: 6 | L22: 6
A23: 25 | B23: B | C23: MH16 | D23: MH-16 Ahmednagar | E23: =VLOOKUP(C23,'[1]sarathi pendency OCT 2021'!$B$2:$G$51,6,0) -> 32.342162 | F23: =VLOOKUP(C23,'[1]vahan pendency_oct2021'!$C$2:$H$51,6,0) -> 63.572827 | G23: =VLOOKUP(C23,'[1]Online Revenue_OCT2021'!$B$2:$O$51,14,0) -> 98.047606 | H23: =VLOOKUP('[1]Final Ranking Nov-21'!C26,'[1]challan pendency'!$B$3:$L$49,11,0) -> 14.624606 | I23: =VLOOKUP(C23,'[1]challan online'!$G$3:$Q$51,11,0) -> 99.209486 | J23: =AVERAGE(E23:I23) -> 61.559337 | K23: 7 | L23: 7
A24: 17 | B24: B | C24: MH24 | D24: MH-24 Latur | E24: =VLOOKUP(C24,'[1]sarathi pendency OCT 2021'!$B$2:$G$51,6,0) -> 48.265105 | F24: =VLOOKUP(C24,'[1]vahan pendency_oct2021'!$C$2:$H$51,6,0) -> 56.188704 | G24: =VLOOKUP(C24,'[1]Online Revenue_OCT2021'!$B$2:$O$51,14,0) -> 96.5248 | H24: =VLOOKUP('[1]Final Ranking Nov-21'!C18,'[1]challan pendency'!$B$3:$L$49,11,0) -> 12.320365 | I24: =VLOOKUP(C24,'[1]challan online'!$G$3:$Q$51,11,0) -> 99.351819 | J24: =AVERAGE(E24:I24) -> 62.530159 | K24: 8 | L24: 8
A25: 21 | B25: B | C25: MH42 | D25: MH-42 Baramati | E25: =VLOOKUP(C25,'[1]sarathi pendency OCT 2021'!$B$2:$G$51,6,0) -> 29.831522 | F25: =VLOOKUP(C25,'[1]vahan pendency_oct2021'!$C$2:$H$51,6,0) -> 55.723496 | G25: =VLOOKUP(C25,'[1]Online Revenue_OCT2021'!$B$2:$O$51,14,0) -> 99.904653 | H25: =VLOOKUP('[1]Final Ranking Nov-21'!C22,'[1]challan pendency'!$B$3:$L$49,11,0) -> 100 | I25: =VLOOKUP(C25,'[1]challan online'!$G$3:$Q$51,11,0) -> 100 | J25: =AVERAGE(E25:I25) -> 77.091934 | K25: 9 | L25: 9
A26: 27 | B26: B | C26: MH26 | D26: MH-26 Nanded | E26: =VLOOKUP(C26,'[1]sarathi pendency OCT 2021'!$B$2:$G$51,6,0) -> 34.132997 | F26: =VLOOKUP(C26,'[1]vahan pendency_oct2021'!$C$2:$H$51,6,0) -> 65.280294 | G26: =VLOOKUP(C26,'[1]Online Revenue_OCT2021'!$B$2:$O$51,14,0) -> 89.053076 | H26: =VLOOKUP('[1]Final Ranking Nov-21'!C28,'[1]challan pendency'!$B$3:$L$49,11,0) -> 2.7318183 | I26: =VLOOKUP(C26,'[1]challan online'!$G$3:$Q$51,11,0) -> 99.234973 | J26: =AVERAGE(E26:I26) -> 58.086631 | K26: 10 | L26: 10
A27: 30 | B27: B | C27: MH49 | D27: MH-49 Nagpur (East) | E27: =VLOOKUP(C27,'[1]sarathi pendency OCT 2021'!$B$2:$G$51,6,0) -> 35.044694 | F27: =VLOOKUP(C27,'[1]vahan pendency_oct2021'!$C$2:$H$51,6,0) -> 47.047386 | G27: =VLOOKUP(C27,'[1]Online Revenue_OCT2021'!$B$2:$O$51,14,0) -> 96.262946 | H27: =VLOOKUP('[1]Final Ranking Nov-21'!C31,'[1]challan pendency'!$B$3:$L$49,11,0) -> 4.1333736 | I27: =VLOOKUP(C27,'[1]challan online'!$G$3:$Q$51,11,0) -> 100 | J27: =AVERAGE(E27:I27) -> 56.49768 | K27: 11 | L27: 11
A28: 26 | B28: B | C28: MH06 | D28: MH-06 Pen (Raigad) | E28: =VLOOKUP(C28,'[1]sarathi pendency OCT 2021'!$B$2:$G$51,6,0) -> 34.49807 | F28: =VLOOKUP(C28,'[1]vahan pendency_oct2021'!$C$2:$H$51,6,0) -> 33.646154 | G28: =VLOOKUP(C28,'[1]Online Revenue_OCT2021'!$B$2:$O$51,14,0) -> 94.258756 | H28: =VLOOKUP('[1]Final Ranking Nov-21'!C27,'[1]challan pendency'!$B$3:$L$49,11,0) -> 10.715993 | I28: =VLOOKUP(C28,'[1]challan online'!$G$3:$Q$51,11,0) -> 100 | J28: =AVERAGE(E28:I28) -> 54.623794 | K28: 12 | L28: 12
A29: 28 | B29: B | C29: MH10 | D29: MH-10 Sangli | E29: =VLOOKUP(C29,'[1]sarathi pendency OCT 2021'!$B$2:$G$51,6,0) -> 40.69686 | F29: =VLOOKUP(C29,'[1]vahan pendency_oct2021'!$C$2:$H$51,6,0) -> 22.777772 | G29: =VLOOKUP(C29,'[1]Online Revenue_OCT2021'!$B$2:$O$51,14,0) -> 97.24812 | H29: =VLOOKUP('[1]Final Ranking Nov-21'!C29,'[1]challan pendency'!$B$3:$L$49,11,0) -> 4.439771 | I29: =VLOOKUP(C29,'[1]challan online'!$G$3:$Q$51,11,0) -> 100 | J29: =AVERAGE(E29:I29) -> 53.032504 | K29: 13 | L29: 13
A30: 24 | B30: B | C30: MH31 | D30: MH-31 Nagpur_City | E30: =VLOOKUP(C30,'[1]sarathi pendency OCT 2021'!$B$2:$G$51,6,0) -> 20.223313 | F30: =VLOOKUP(C30,'[1]vahan pendency_oct2021'!$C$2:$H$51,6,0) -> 54.62069 | G30: =VLOOKUP(C30,'[1]Online Revenue_OCT2021'!$B$2:$O$51,14,0) -> 95.243694 | H30: =VLOOKUP('[1]Final Ranking Nov-21'!C25,'[1]challan pendency'!$B$3:$L$49,11,0) -> 3.5962145 | I30: =VLOOKUP(C30,'[1]challan online'!$G$3:$Q$51,11,0) -> 88.028169 | J30: =AVERAGE(E30:I30) -> 52.342416 | K30: 14 | L30: 14
A31: 29 | B31: B | C31: MH19 | D31: MH-19 Jalgaon | E31: =VLOOKUP(C31,'[1]sarathi pendency OCT 2021'!$B$2:$G$51,6,0) -> 26.716106 | F31: =VLOOKUP(C31,'[1]vahan pendency_oct2021'!$C$2:$H$51,6,0) -> 34.175132 | G31: =VLOOKUP(C31,'[1]Online Revenue_OCT2021'!$B$2:$O$51,14,0) -> 96.797228 | H31: =VLOOKUP('[1]Final Ranking Nov-21'!C30,'[1]challan pendency'!$B$3:$L$49,11,0) -> 4.5031963 | I31: =VLOOKUP(C31,'[1]challan online'!$G$3:$Q$51,11,0) -> 98.480463 | J31: =AVERAGE(E31:I31) -> 52.134425 | K31: 15 | L31: 15
A32: 32 | B32: C | C32: MH32 | D32: MH-32 Wardha | E32: 63.657152 | F32: 100 | G32: 90.950746 | H32: =VLOOKUP(C32,'[1]challan pendency'!$B$3:$L$52,11,0) -> 8.8906414 | I32: =VLOOKUP(C32,'[1]challan online'!$G$3:$Q$52,11,0) -> 100 | J32: 71.81158 | K32: 1 | L32: 1
A33: 33 | B33: C | C33: MH37 | D33: MH-37 Washim | E33: 41.771093 | F33: 96.093023 | G33: 93.197957 | H33: =VLOOKUP(C33,'[1]challan pendency'!$B$3:$L$52,11,0) -> 5.1146162 | I33: =VLOOKUP(C33,'[1]challan online'!$G$3:$Q$52,11,0) -> 100 | J33: 66.724415 | K33: 2 | L33: 2
A34: 34 | B34: C | C34: MH38 | D34: MH-38 Hingoli | E34: 38.078864 | F34: 94.656977 | G34: 98.520951 | H34: =VLOOKUP(C34,'[1]challan pendency'!$B$3:$L$52,11,0) -> 3.3020797 | I34: =VLOOKUP(C34,'[1]challan online'!$G$3:$Q$52,11,0) -> 100 | J34: 66.581914 | K34: 3 | L34: 3
A35: 35 | B35: C | C35: MH33 | D35: MH-33 Gadchiroli | E35: 41.30516 | F35: 65.464366 | G35: 97.95381 | H35: =VLOOKUP(C35,'[1]challan pendency'!$B$3:$L$52,11,0) -> 41.099594 | I35: =VLOOKUP(C35,'[1]challan online'!$G$3:$Q$52,11,0) -> 100 | J35: 65.058953 | K35: 4 | L35: 4
A36: 36 | B36: C | C36: MH35 | D36: MH-35 Gondia | E36: 46.710564 | F36: 82.364074 | G36: 83.615817 | H36: =VLOOKUP(C36,'[1]challan pendency'!$B$3:$L$52,11,0) -> 6.8110123 | I36: =VLOOKUP(C36,'[1]challan online'!$G$3:$Q$52,11,0) -> 100 | J36: 63.219909 | K36: 5 | L36: 5
A37: 37 | B37: C | C37: MH50 | D37: MH-50 Karad | E37: 67.874575 | F37: 47.98214 | G37: 96.107366 | H37: =VLOOKUP(C37,'[1]challan pendency'!$B$3:$L$52,11,0) -> 2.5306695 | I37: =VLOOKUP(C37,'[1]challan online'!$G$3:$Q$52,11,0) -> 99.013158 | J37: 62.448781 | K37: 6 | L37: 6
A38: 38 | B38: C | C38: MH30 | D38: MH-30 Akola | E38: 53.902101 | F38: 51.337674 | G38: 99.132635 | H38: =VLOOKUP(C38,'[1]challan pendency'!$B$3:$L$52,11,0) -> 2.8593755 | I38: =VLOOKUP(C38,'[1]challan online'!$G$3:$Q$52,11,0) -> 99.358974 | J38: 61.032516 | K38: 7 | L38: 7
A39: 39 | B39: C | C39: MH36 | D39: MH-36 Bhandara | E39: 49.686265 | F39: 60.657807 | G39: 89.18345 | H39: =VLOOKUP(C39,'[1]challan pendency'!$B$3:$L$52,11,0) -> 5.6940063 | I39: =VLOOKUP(C39,'[1]challan online'!$G$3:$Q$52,11,0) -> 100 | J39: 60.475504 | K39: 8 | L39: 8
A40: 40 | B40: C | C40: MH28 | D40: MH-28 Buldhana | E40: 32.72343 | F40: 67.2914 | G40: 98.785006 | H40: =VLOOKUP(C40,'[1]challan pendency'!$B$3:$L$52,11,0) -> 3.4282095 | I40: =VLOOKUP(C40,'[1]challan online'!$G$3:$Q$52,11,0) -> 100 | J40: 60.103149 | K40: 9 | L40: 9
...

Sheet max cash table
A1: Sr No | B1: RTO Code | C1: RTO Name | D1: Sarathi Revenue Cash | E1: Sarathi Revenue Online | F1: Total Sarathi Revenue | G1: Vahan Revenue Cash | H1: Vahan Revenue Online | I1: Vahan Revenue Others | J1: Total Vahan Revenue | K1: Total Cash Revenue | L1: Total Online Revenue | M1: Total Revenue | N1: Cash Payment % | O1: Marks
A2: 1 | B2: MH35 | C2: GONDHIA | D2: 0 | E2: 4277199 | F2: 4277199 | G2: 5213896 | H2: 23921049 | I2: 47933 | J2: =SUM(G2:I2) -> 29182878 | K2: =+D2+G2 -> 5213896 | L2: =+E2+H2 -> 28198248 | M2: =+F2+J2 -> 33460077 | N2: =(K2/M2) -> 0.15582439 | O2: 100
A3: 2 | B3: MH34 | C3: CHANDRAPUR | D3: 0 | E3: 1441907 | F3: 1441907 | G3: 10569695 | H3: 69567144 | I3: 85050 | J3: =SUM(G3:I3) -> 80221889 | K3: =+D3+G3 -> 10569695 | L3: =+E3+H3 -> 71009051 | M3: =+F3+J3 -> 81663796 | N3: =(K3/M3) -> 0.12942939 | O3: =(N3/$N$2)*$O$2 -> 83.061059
A4: 3 | B4: MH26 | C4: NANDED | D4: 0 | E4: 2796084 | F4: 2796084 | G4: 9133283 | H4: 71995068 | I4: 647600 | J4: =SUM(G4:I4) -> 81775951 | K4: =+D4+G4 -> 9133283 | L4: =+E4+H4 -> 74791152 | M4: =+F4+J4 -> 84572035 | N4: =(K4/M4) -> 0.10799413 | O4: =(N4/$N$2)*$O$2 -> 69.305022
A5: 4 | B5: MH36 | C5: BHANDARA | D5: 0 | E5: 2259109 | F5: 2259109 | G5: 3639376 | H5: 29233087 | I5: 0 | J5: =SUM(G5:I5) -> 32872463 | K5: =+D5+G5 -> 3639376 | L5: =+E5+H5 -> 31492196 | M5: =+F5+J5 -> 35131572 | N5: =(K5/M5) -> 0.10359275 | O5: =(N5/$N$2)*$O$2 -> 66.480445
A6: 5 | B6: MH40 | C6: NAGPUR (RURAL) | D6: 0 | E6: 2129724 | F6: 2129724 | G6: 11812219 | H6: 121687058 | I6: 3538072 | J6: =SUM(G6:I6) -> 137037349 | K6: =+D6+G6 -> 11812219 | L6: =+E6+H6 -> 123816782 | M6: =+F6+J6 -> 139167073 | N6: =(K6/M6) -> 0.084877973 | O6: =(N6/$N$2)*$O$2 -> 54.470275
A7: 6 | B7: MH32 | C7: WARDHA | D7: 0 | E7: 6130098 | F7: 6130098 | G7: 2749734 | H7: 30290913 | I7: 691077 | J7: =SUM(G7:I7) -> 33731724 | K7: =+D7+G7 -> 2749734 | L7: =+E7+H7 -> 36421011 | M7: =+F7+J7 -> 39861822 | N7: =(K7/M7) -> 0.068981644 | O7: =(N7/$N$2)*$O$2 -> 44.268837
A8: 7 | B8: MH37 | C8: WASHIM | D8: 0 | E8: 2481301 | F8: 2481301 | G8: 1874631 | H8: 24945524 | I8: 0 | J8: =SUM(G8:I8) -> 26820155 | K8: =+D8+G8 -> 1874631 | L8: =+E8+H8 -> 27426825 | M8: =+F8+J8 -> 29301456 | N8: =(K8/M8) -> 0.063977401 | O8: =(N8/$N$2)*$O$2 -> 41.057374
A9: 8 | B9: MH07 | C9: SINDHUDURG | D9: 300 | E9: 2964688 | F9: 2964988 | G9: 1721158 | H9: 26171420 | I9: 0 | J9: =SUM(G9:I9) -> 27892578 | K9: =+D9+G9 -> 1721458 | L9: =+E9+H9 -> 29136108 | M9: =+F9+J9 -> 30857566 | N9: =(K9/M9) -> 0.055787226 | O9: =(N9/$N$2)*$O$2 -> 35.801344
A10: 9 | B10: MH41 | C10: MALEGAON | D10: 0 | E10: 4080582 | F10: 4080582 | G10: 2658237 | H10: 40750280 | I10: 309608 | J10: =SUM(G10:I10) -> 43718125 | K10: =+D10+G10 -> 2658237 | L10: =+E10+H10 -> 44830862 | M10: =+F10+J10 -> 47798707 | N10: =(K10/M10) -> 0.055613157 | O10: =(N10/$N$2)*$O$2 -> 35.689636
A11: 10 | B11: MH06 | C11: PEN (RAIGAD) | D11: 0 | E11: 10808827 | F11: 10808827 | G11: 4217592 | H11: 63275236 | I11: 305000 | J11: =SUM(G11:I11) -> 67797828 | K11: =+D11+G11 -> 4217592 | L11: =+E11+H11 -> 74084063 | M11: =+F11+J11 -> 78606655 | N11: =(K11/M11) -> 0.053654388 | O11: =(N11/$N$2)*$O$2 -> 34.4326
A12: 11 | B12: MH31 | C12: NAGPUR (U) | D12: 0 | E12: 3979505 | F12: 3979505 | G12: 5400295 | H12: 90913766 | I12: 1861642 | J12: =SUM(G12:I12) -> 98175703 | K12: =+D12+G12 -> 5400295 | L12: =+E12+H12 -> 94893271 | M12: =+F12+J12 -> 102155208 | N12: =(K12/M12) -> 0.052863629 | O12: =(N12/$N$2)*$O$2 -> 33.925132
A13: 12 | B13: MH20 | C13: AURANGABAD | D13: 0 | E13: 6624832 | F13: 6624832 | G13: 9344151 | H13: 166035698 | I13: 1998231 | J13: =SUM(G13:I13) -> 177378080 | K13: =+D13+G13 -> 9344151 | L13: =+E13+H13 -> 172660530 | M13: =+F13+J13 -> 184002912 | N13: =(K13/M13) -> 0.050782626 | O13: =(N13/$N$2)*$O$2 -> 32.589652
A14: 13 | B14: MH25 | C14: OSMANABAD | D14: 0 | E14: 5045386 | F14: 5045386 | G14: 2063745 | H14: 35443274 | I14: 206467 | J14: =SUM(G14:I14) -> 37713486 | K14: =+D14+G14 -> 2063745 | L14: =+E14+H14 -> 40488660 | M14: =+F14+J14 -> 42758872 | N14: =(K14/M14) -> 0.04826472 | O14: =(N14/$N$2)*$O$2 -> 30.973791
... A38: 37 | B38: MH23 | C38: BEED | D38: 0 | E38: 3808696 | F38: 3808696 | G38: 374000 | H38: 44153203 | I38: 2204425 | J38: =SUM(G38:I38) -> 46731628 | K38: =+D38+G38 -> 374000 | L38: =+E38+H38 -> 47961899 | M38: =+F38+J38 -> 50540324 | N38: =(K38/M38) -> 0.0074000317 | O38: =(N38/$N$2)*$O$2 -> 4.7489561
A39: 38 | B39: MH09 | C39: KOLHAPUR | D39: 0 | E39: 4159333 | F39: 4159333 | G39: 1473345 | H39: 194783982 | I39: 1450125 | J39: =SUM(G39:I39) -> 197707452 | K39: =+D39+G39 -> 1473345 | L39: =+E39+H39 -> 198943315 | M39: =+F39+J39 -> 201866785 | N39: =(K39/M39) -> 0.0072986004 | O39: 100
A40: 39 | B40: MH47 | C40: BORIVALI | D40: 0 | E40: 5305572 | F40: 5305572 | G40: 1821928 | H40: 241123048 | I40: 4456288 | J40: =SUM(G40:I40) -> 247401264 | K40: =+D40+G40 -> 1821928 | L40: =+E40+H40 -> 246428620 | M40: =+F40+J40 -> 252706836 | N40: =(K40/M40) -> 0.0072096506 | O40: =(N40/$N$2)*$O$2 -> 4.6267794
A41: 40 | B41: MH13 | C41: SOLAPUR | D41: 0 | E41: 27364331 | F41: 27364331 | G41: 571063 | H41: 102690475 | I41: 918388 | J41: =SUM(G41:I41) -> 104179926 | K41: =+D41+G41 -> 571063 | L41: =+E41+H41 -> 130054806 | M41: =+F41+J41 -> 131544257 | N41: =(K41/M41) -> 0.0043412233 | O41: =(N41/$N$2)*$O$2 -> 2.7859717
A42: 41 | B42: MH02 | C42: MUMBAI (WEST) | D42: 0 | E42: 17355920 | F42: 17355920 | G42: 1569970 | H42: 366870418 | I42: 5877463 | J42: =SUM(G42:I42) -> 374317851 | K42: =+D42+G42 -> 1569970 | L42: =+E42+H42 -> 384226338 | M42: =+F42+J42 -> 391673771 | N42: =(K42/M42) -> 0.0040083613 | O42: =(N42/$N$2)*$O$2 -> 2.5723582
A43: 42 | B43: MH03 | C43: MUMBAI (EAST) | D43: 0 | E43: 17766451 | F43: 17766451 | G43: 1037755 | H43: 296353024 | I43: 4506326 | J43: =SUM(G43:I43) -> 301897105 | K43: =+D43+G43 -> 1037755 | L43: =+E43+H43 -> 314119475 | M43: =+F43+J43 -> 319663556 | N43: =(K43/M43) -> 0.0032463976 | O43: =(N43/$N$2)*$O$2 -> 2.0833694
A44: 43 | B44: MH18 | C44: DHULE | D44: 0 | E44: 3801746 | F44: 3801746 | G44: 151238 | H44: 69526378 | I44: 493705 | J44: =SUM(G44:I44) -> 70171321 | K44: =+D44+G44 -> 151238 | L44: =+E44+H44 -> 73328124 | M44: =+F44+J44 -> 73973067 | N44: =(K44/M44) -> 0.0020445009 | O44: =(N44/$N$2)*$O$2 -> 1.3120545
A45: 44 | B45: MH12 | C45: PUNE | D45: 0 | E45: 6748150 | F45: 6748150 | G45: 1018076 | H45: 864410455 | I45: 19140204 | J45: =SUM(G45:I45) -> 884568735 | K45: =+D45+G45 -> 1018076 | L45: =+E45+H45 -> 871158605 | M45: =+F45+J45 -> 891316885 | N45: =(K45/M45) -> 0.0011422155 | O45: =(N45/$N$2)*$O$2 -> 0.73301462
A46: 45 | B46: MH01 | C46: MUMBAI (CENTRAL) | D46: 300 | E46: 324560219 | F46: 324560519 | G46: 337376 | H46: 405943553 | I46: 8381752 | J46: =SUM(G46:I46) -> 414662681 | K46: =+D46+G46 -> 337676 | L46: =+E46+H46 -> 730503772 | M46: =+F46+J46 -> 739223200 | N46: =(K46/M46) -> 0.00045679843 | O46: =(N46/$N$2)*$O$2 -> 0.29314951
A47: 46 | B47: MH45 | C47: AKLUJ | D47: 0 | E47: 3881375 | F47: 3881375 | G47: 7554 | H47: 42700259 | I47: 575322 | J47: =SUM(G47:I47) -> 43283135 | K47: =+D47+G47 -> 7554 | L47: =+E47+H47 -> 46581634 | M47: =+F47+J47 -> 47164510 | N47: =(K47/M47) -> 0.0001601628 | O47: =(N47/$N$2)*$O$2 -> 0.10278417
A48: 47 | B48: MH44 | C48: AMBEJOGAI | D48: 0 | E48: 5168070 | F48: 5168070 | G48: 3298 | H48: 30563529 | I48: 27812 | J48: =SUM(G48:I48) -> 30594639 | K48: =+D48+G48 -> 3298 | L48: =+E48+H48 -> 35731599 | M48: =+F48+J48 -> 35762709 | N48: =(K48/M48) -> 9.2218965e-05 | O48: =(N48/$N$2)*$O$2 -> 0.059181343
A49: 48 | B49: MH42 | C49: BARAMATI | D49: 0 | E49: 2544079 | F49: 2544079 | G49: 4300 | H49: 77084160 | I49: 557232 | J49: =SUM(G49:I49) -> 77645692 | K49: =+D49+G49 -> 4300 | L49: =+E49+H49 -> 79628239 | M49: =+F49+J49 -> 80189771 | N49: =(K49/M49) -> 5.3622799e-05 | O49: =(N49/$N$2)*$O$2 -> 0.034412328
A50: 49 | B50: MH14 | C50: PIMPRI-CHINCHWAD | D50: 0 | E50: 8731946 | F50: 8731946 | G50: 1285 | H50: 489041661 | I50: 14641176 | J50: =SUM(G50:I50) -> 503684122 | K50: =+D50+G50 -> 1285 | L50: =+E50+H50 -> 497773607 | M50: =+F50+J50 -> 512416068 | N50: =(K50/M50) -> 2.5077278e-06 | O50: =(N50/$N$2)*$O$2 -> 0.0016093295
A51: 50 | B51: MH21 | C51: JALANA | D51: 0 | E51: 6647979 | F51: 6647979 | G51: 0 | H51: 43684878 | I51: 459596 | J51: =SUM(G51:I51) -> 44144474 | K51: =+D51+G51 -> 0 | L51: =+E51+H51 -> 50332857 | M51: =+F51+J51 -> 50792453 | N51: =(K51/M51) -> 0 | O51: =(N51/$N$2)*$O$2 -> 0
C52: Total | D52: 0 | E52: 2957150 | F52: 2957150 | G52: =SUM(G2:G51) -> 155525964 | H52: =SUM(H2:H51) -> 6649091228 | I52: =SUM(I2:I51) -> 118344540 | J52: =SUM(J2:J51) -> 6922961732 | K52: =SUM(K2:K51) -> 155526564 | L52: =SUM(L2:L51) -> 7295254516 | M52: =SUM(M2:M51) -> 7569125620

Sheet Online Revenue_Nov 2021
A1: Sr No | B1: RTO Code | C1: RTO Name | D1: Sarathi Revenue Cash | E1: Sarathi Revenue Online | F1: Total Sarathi Revenue | G1: Vahan Revenue Cash | H1: Vahan Revenue Online | I1: Vahan Revenue Others | J1: Total Vahan Revenue | K1: Total Cash Revenue | L1: Total Online Revenue | M1: Total Revenue | N1: Online Payment % | O1: Marks
A2: 21 | B2: MH21 | C2: MH21-DY.RTO,JALNA | D2: 0 | E2: 2208021 | F2: 2208021 | G2: 0 | H2: 69692312 | I2: 268453 | J2: =SUM(G2:I2) -> 69960765 | K2: =+D2+G2 -> 0 | L2: =+E2+H2 -> 71900333 | M2: =+F2+J2 -> 72168786 | N2: =(L2/M2) -> 0.99628021 | O2: 100
A3: 18 | B3: MH18 | C3: MH18-DY.RTO,DHULE | D3: 0 | E3: 3414407 | F3: 3414407 | G3: 293610 | H3: 116241003 | I3: 761218 | J3: =SUM(G3:I3) -> 117295831 | K3: =+D3+G3 -> 293610 | L3: =+E3+H3 -> 119655410 | M3: =+F3+J3 -> 120710238 | N3: =(L3/M3) -> 0.99126149 | O3: =(N3/$N$2)*$O$2 -> 99.496254
A4: 13 | B4: MH13 | C4: MH13-DY.RTO,SOLAPUR | D4: 0 | E4: 6460870 | F4: 6460870 | G4: 691340 | H4: 130894635 | I4: 571812 | J4: =SUM(G4:I4) -> 132157787 | K4: =+D4+G4 -> 691340 | L4: =+E4+H4 -> 137355505 | M4: =+F4+J4 -> 138618657 | N4: =(L4/M4) -> 0.99088758 | O4: =(N4/$N$2)*$O$2 -> 99.458724
A5: 14 | B5: MH14 | C5: MH14-DY.RTO,PIMPRI-CHINCHWAD | D5: 0 | E5: 12465897 | F5: 12465897 | G5: 600 | H5: 579961436 | I5: 5608693 | J5: =SUM(G5:I5) -> 585570729 | K5: =+D5+G5 -> 600 | L5: =+E5+H5 -> 592427333 | M5: =+F5+J5 -> 598036626 | N5: =(L5/M5) -> 0.99062049 | O5: =(N5/$N$2)*$O$2 -> 99.431915
A6: 8 | B6: MH08 | C6: MH08-DY.RTO,RATNAGIRI | D6: 0 | E6: 3191126 | F6: 3191126 | G6: 499174 | H6: 67457269 | I6: 337718 | J6: =SUM(G6:I6) -> 68294161 | K6: =+D6+G6 -> 499174 | L6: =+E6+H6 -> 70648395 | M6: =+F6+J6 -> 71485287 | N6: =(L6/M6) -> 0.98829281 | O6: =(N6/$N$2)*$O$2 -> 99.198278
A7: 16 | B7: MH16 | C7: MH16-DY.RTO,AHMEDNAGAR | D7: 0 | E7: 4386955 | F7: 4386955 | G7: 1662734 | H7: 114873625 | I7: 17000 | J7: =SUM(G7:I7) -> 116553359 | K7: =+D7+G7 -> 1662734 | L7: =+E7+H7 -> 119260580 | M7: =+F7+J7 -> 120940314 | N7: =(L7/M7) -> 0.98611105 | O7: =(N7/$N$2)*$O$2 -> 98.979288
A8: 1 | B8: MH01 | C8: MH01-RTO,MUMBAI CENTRAL | D8: 0 | E8: 16277914 | F8: 16277914 | G8: 164117 | H8: 417878495 | I8: 6959132 | J8: =SUM(G8:I8) -> 425001744 | K8: =+D8+G8 -> 164117 | L8: =+E8+H8 -> 434156409 | M8: =+F8+J8 -> 441279658 | N8: =(L8/M8) -> 0.98385774 | O8: =(N8/$N$2)*$O$2 -> 98.753116
A9: 2 | B9: MH02 | C9: MH02-RTO,MUMBAI (WEST | D9: 0 | E9: 13791391 | F9: 13791391 | G9: 916682 | H9: 370871611 | I9: 5470198 | J9: =SUM(G9:I9) -> 377258491 | K9: =+D9+G9 -> 916682 | L9: =+E9+H9 -> 384663002 | M9: =+F9+J9 -> 391049882 | N9: =(L9/M9) -> 0.98366735 | O9: =(N9/$N$2)*$O$2 -> 98.734005
A10: 22 | B10: MH22 | C10: MH22-DY.RTO,PARBHANI | D10: 0 | E10: 3126779 | F10: 3126779 | G10: 923840 | H10: 48550410 | I10: 4000 | J10: =SUM(G10:I10) -> 49478250 | K10: =+D10+G10 -> 923840 | L10: =+E10+H10 -> 51677189 | M10: =+F10+J10 -> 52605029 | N10: =(L10/M10) -> 0.98236214 | O10: =(N10/$N$2)*$O$2 -> 98.602997
A11: 12 | B11: MH12 | C11: MH12-RTO,PUNE | D11: 0 | E11: 23030923 | F11: 23030923 | G11: 42500 | H11: 921953846 | I11: 18451551 | J11: =SUM(G11:I11) -> 940447897 | K11: =+D11+G11 -> 42500 | L11: =+E11+H11 -> 944984769 | M11: =+F11+J11 -> 963478820 | N11: =(L11/M11) -> 0.98080492 | O11: =(N11/$N$2)*$O$2 -> 98.446694
A12: 23 | B12: MH23 | C12: MH23-DY.RTO,BEED | D12: 0 | E12: 2720201 | F12: 2720201 | G12: 0 | H12: 62934786 | I12: 1361361 | J12: =SUM(G12:I12) -> 64296147 | K12: =+D12+G12 -> 0 | L12: =+E12+H12 -> 65654987 | M12: =+F12+J12 -> 67016348 | N12: =(L12/M12) -> 0.97968614 | O12: =(N12/$N$2)*$O$2 -> 98.334397
A13: 9 | B13: MH09 | C13: MH09-RTO,KOLHAPUR | D13: 0 | E13: 10241151 | F13: 10241151 | G13: 4431680 | H13: 231565476 | I13: 1109918 | J13: =SUM(G13:I13) -> 237107074 | K13: =+D13+G13 -> 4431680 | L13: =+E13+H13 -> 241806627 | M13: =+F13+J13 -> 247348225 | N13: =(L13/M13) -> 0.97759597 | O13: =(N13/$N$2)*$O$2 -> 98.1246
A14: 17 | B14: MH17 | C14: MH17-DY.RTO,SHRIRAMPUR | D14: 0 | E14: 3379223 | F14: 3379223 | G14: 1501421 | H14: 74122509 | I14: 379546 | J14: =SUM(G14:I14) -> 76003476 | K14: =+D14+G14 -> 1501421 | L14: =+E14+H14 -> 77501732 | M14: =+F14+J14 -> 79382699 | N14: =(L14/M14) -> 0.97630508 | O14: =(N14/$N$2)*$O$2 -> 97.995029
... A51: 50 | B51: MH50 | C51: MH50-DY.RTO, KARAD | D51: 0 | E51: 2636774 | F51: 2636774 | G51: 5213896 | H51: 23921049 | I51: 47933 | J51: =SUM(G51:I51) -> 29182878 | K51: =+D51+G51 -> 5213896 | L51: =+E51+H51 -> 26557823 | M51: =+F51+J51 -> 31819652 | N51: =(L51/M51) -> 0.83463587 | O51: =(N51/$N$2)*$O$2 -> 83.775214
C52: Total | D52: 0 | E52: =SUM(E2:E51) -> 287941263 | F52: =SUM(F2:F51) -> 287941613 | G52: =SUM(G2:G51) -> 209534615 | H52: =SUM(H2:H51) -> 7882363326 | I52: =SUM(I2:I51) -> 129773377 | J52: =SUM(J2:J51) -> 8221671318 | K52: =SUM(K2:K51) -> 209534965 | L52: =SUM(L2:L51) -> 8170304589 | M52: =SUM(M2:M51) -> 8509612931

Sheet sarathi pendency Nov 2021
A1: S.No | B1: RTO Office Code | C1: Name Of The RTO Office | D1: Applications Received | E1: Pending at Office | F1: Pendency | G1: Marks
A2: 48 | B2: MH48 | C2: DY. RTO VASAI-VIRAR | D2: 16255 | E2: 5169 | F2: =(E2/D2) -> 0.31799446 | G2: =($F$51/F2)*$G$51 -> 17.784191
A3: 49 | B3: MH49 | C3: DY.RTO, NAGPUR (EAST) | D3: 14478 | E3: 4188 | F3: =(E3/D3) -> 0.28926647 | G3: =($F$51/F3)*$G$51 -> 19.550396
A4: 8 | B4: MH08 | C4: DY.RTO,RATNAGIRI | D4: 8022 | E4: 2263 | F4: =(E4/D4) -> 0.28209923 | G4: =($F$51/F4)*$G$51 -> 20.04711
A5: 40 | B5: MH40 | C5: RTO,NAGPUR_RURAL | D5: 9134 | E5: 2514 | F5: =(E5/D5) -> 0.27523538 | G5: =($F$51/F5)*$G$51 -> 20.547046
A6: 46 | B6: MH46 | C6: RTO, PANVEL | D6: 12826 | E6: 3501 | F6: =(E6/D6) -> 0.27296117 | G6: =($F$51/F6)*$G$51 -> 20.718237
A7: 31 | B7: MH31 | C7: RTO,NAGPUR_CITY | D7: 13428 | E7: 3261 | F7: =(E7/D7) -> 0.24285076 | G7: =($F$51/F7)*$G$51 -> 23.287035
A8: 34 | B8: MH34 | C8: DY. RTO,CHANDRAPUR | D8: 7977 | E8: 1886 | F8: =(E8/D8) -> 0.23642974 | G8: =($F$51/F8)*$G$51 -> 23.919471
A9: 19 | B9: MH19 | C9: DY.RTO,JALGAON | D9: 14857 | E9: 3462 | F9: =(E9/D9) -> 0.23302147 | G9: =($F$51/F9)*$G$51 -> 24.269326
A10: 9 | B10: MH09 | C10: RTO,KOLHAPUR | D10: 23110 | E10: 5341 | F10: =(E10/D10) -> 0.23111207 | G10: =($F$51/F10)*$G$51 -> 24.469834
A11: 5 | B11: MH05 | C11: DY.RTO,KALYAN | D11: 24160 | E11: 5504 | F11: =(E11/D11) -> 0.22781457 | G11: =($F$51/F11)*$G$51 -> 24.824023
A12: 7 | B12: MH07 | C12: DY.RTO,SINDHUDURG | D12: 4577 | E12: 956 | F12: =(E12/D12) -> 0.20887044 | G12: =($F$51/F12)*$G$51 -> 27.075512
A13: 4 | B13: MH04 | C13: RTO,THANE | D13: 33559 | E13: 6915 | F13: =(E13/D13) -> 0.20605501 | G13: =($F$51/F13)*$G$51 -> 27.445458
... A50: 32 | B50: MH32 | C50: DY. RTO,WARDHA | D50: 4660 | E50: 435 | F50: =(E50/D50) -> 0.093347639 | G50: =($F$51/F50)*$G$51 -> 60.582937
A51: 11 | B51: MH11 | C51: DY.RTO,SATARA | D51: 12201 | E51: 690 | F51: =(E51/D51) -> 0.056552742 | G51: 100
A52: Total | D52: =SUM(D2:D51) -> 641581 | E52: =SUM(E2:E51) -> 114598

Sheet vahan pendency_Nov 2021
A1: Sr. No. | B1: RTO Name | C1: RTO Code | D1: Total Applications received | E1: Pending applications | F1: Pendency | G1: Marks
A2: 2 | B2: AKLUJ ( MH-45 ) | C2: 45 | D2: 4989 | E2: 1006 | F2: =(E2/D2) -> 0.20164362 | G2: =($F$51/F2)*$G$51 -> 21.150593
A3: 4 | B3: AMBEJOGAI ( MH-44 ) | C3: 44 | D3: 4041 | E3: 630 | F3: =(E3/D3) -> 0.155902 | G3: =($F$51/F3)*$G$51 -> 27.356173
A4: 40 | B4: SANGLI ( MH-10 ) | C4: 10 | D4: 14926 | E4: 2257 | F4: =(E4/D4) -> 0.15121265 | G4: =($F$51/F4)*$G$51 -> 28.204533
A5: 25 | B5: MALEGAON ( MH-41 ) | C5: 41 | D5: 6423 | E5: 905 | F5: =(E5/D5) -> 0.14089989 | G5: =($F$51/F5)*$G$51 -> 30.268882
A6: 23 | B6: KOLHAPUR ( MH-9 ) | C6: 9 | D6: 23897 | E6: 3338 | F6: =(E6/D6) -> 0.13968281 | G6: =($F$51/F6)*$G$51 -> 30.532621
A7: 8 | B7: BEED ( MH-23 ) | C7: 23 | D7: 4026 | E7: 520 | F7: =(E7/D7) -> 0.12916046 | G7: =($F$51/F7)*$G$51 -> 33.02003
A8: 28 | B8: MUMBAI (WEST) ( MH-2 ) | C8: 2 | D8: 14593 | E8: 1738 | F8: =(E8/D8) -> 0.1190982 | G8: =($F$51/F8)*$G$51 -> 35.809796
A9: 33 | B9: NANDURBAR ( MH-39 ) | C9: 39 | D9: 2570 | E9: 290 | F9: =(E9/D9) -> 0.11284047 | G9: =($F$51/F9)*$G$51 -> 37.79568
A10: 29 | B10: NAGPUR (EAST) ( MH-49 ) | C10: 49 | D10: 10885 | E10: 1146 | F10: =(E10/D10) -> 0.1052825 | G10: =($F$51/F10)*$G$51 -> 40.508937
A11: 20 | B11: JALGAON ( MH-19 ) | C11: 19 | D11: 12171 | E11: 1266 | F11: =(E11/D11) -> 0.10401775 | G11: =($F$51/F11)*$G$51 -> 41.001485
A12: 31 | B12: NAGPUR (U) ( MH-31 ) | C12: 31 | D12: 5952 | E12: 600 | F12: =(E12/D12) -> 0.10080645 | G12: =($F$51/F12)*$G$51 -> 42.307631
A13: 15 | B13: RATNAGIRI ( MH-8 ) | C13: 8 | D13: 5446 | E13: 534 | F13: =(E13/D13) -> 0.098053617 | G13: =($F$51/F13)*$G$51 -> 43.495409
... A50: 24 | B50: LATUR ( MH-24 ) | C50: 24 | D50: 8643 | E50: 417 | F50: =(E50/D50) -> 0.048247136 | G50: =($F$51/F50)*$G$51 -> 88.396586
A51: 12 | B51: DHULE ( MH-18 ) | C51: 18 | D51: 10012 | E51: 427 | F51: =(E51/D51) -> 0.042648821 | G51: 100
